Workbook

Sheet はじめに
A2: 紬（つむぎ）｜この事業の変わらない中身
A3: 2026-09-14改定。価格の正本はサイト、Excelは事業検討と配布のための写しです。
B5: シート | C5: 何が入っているか | D5: 性格
A6: 台帳 | B6: 料金レバー | C6: すべての金額の入力欄。青い数字がここにだけある。ここを直すと他のシートが追随する | D6: 直す
B7: 制作プラン | C7: 3プラン＋シングル。料金と作業枠は2026-09-14改定。着手50%・検収50%、継続支援は月単位。 | D7: 計算
B8: 運用プラン | C8: 4プラン。月額と、含まれるもの | D8: 計算
B9: オプション・標準装備 | C9: 別途いただくもの8件と、標準で含むもの5件 | D9: 読む
B10: 変更と継続支援 | C10: 何回でも無料の9件と、別途お見積りの6件 | D10: 読む
B11: 月額制との比較 | C11: 36か月の総額。当方が高くなる行も残してある | D11: 計算
B12: 補助金 | C12: 持続化補助金のパッケージと、補助額・自己負担の計算 | D12: 計算
B13: ポータル掲載費 | C13: 食べログの各プランと、1段下げた差額で運用費が出るか | D13: 計算
A14: 中身 | B14: 納品する仕様20 | C14: 全業種共通の20項目と、その根拠 | D14: 読む
B15: 売らないもの | C15: 売らないと決めた5件と、その理由 | D15: 読む
B16: 業種別 | C16: 4業種の必ず入れるもの／作らないもの／財源／推奨プラン | D16: 読む
B17: ページ一覧 | C17: サイトの21ページ | D17: 読む
B18: 事業の基本 | C18: 屋号・対応エリア・約束・実測値 | D18: 読む
A19: 配布 | B19: 配布用_料金表 | C19: お客様にそのまま見せられる料金表。計算式なし | D19: 見せる
B20: 配布用_36か月の総額 | C20: 月額制との総額比較。お客様にそのまま見せられる | D20: 見せる
A22: 凡例と、触るときの約束
B24: ■ | C24: 青い数字＝直していい入力欄。『料金レバー』にしか置いていない
B25: ■ | C25: 黒い数字＝計算式。直接書き換えない（レバーを直せば動く）
B26: ■ | C26: この本は写し。正本は src/content/prices.ts
B27: ■ | C27: サイトに出る金額を変えるときは prices.ts を直す。この Excel を直してもサイトは変わらない
B28: ■ | C28: prices.ts を直したら npm run build → verify.py。表示と正本の一致は機械が見ている

Sheet 事業の基本
A2: 事業の基本
A3: 屋号・対応エリア・お約束・測った数字。
A5: 項目 | B5: 内容 | C5: 備考
A6: 屋号 | B6: 紬（つむぎ） | C6: 一文字の漢字。読みを括弧で添える
A7: 事業 | B7: 小規模事業者向けのホームページ制作と運用 | C7: 本人の月140時間を計画上限にする
A8: 対応エリア | B8: 全国 | C8: 打ち合わせはオンラインと電話。全国どこでもお受けします。
A9: 対象業種 | B9: 顧客業種は未定。課題別に最初の6件で検証 | C9: 値段を業種で変えず、価値と工数を検証
A10: 一番の主張 | B10: 借地権のホームページか、所有権のホームページか | C10: 月額制は借地。やめた日に更地。当方は土地ごと渡す
A11: 所有の4要素 | B11: ① 住所＝ドメイン ② 建物＝ソースコード ③ 地盤＝置き場所 ④ 家具＝写真と原稿 | C11: どれも『その場で確かめられる形』にしてある
A12: 返答のお約束 | B12: 1営業日以内 | C12: 実績値は計測を始めてから載せる
A13: 表示速度（実測） | B13: 最新の検証レポートを参照 | C13: 毎回のビルドで測り直す。手で書かない
A14: 実行時JavaScript | B14: 0バイト（全21ページ） | C14: ③地盤の根拠。アイランドを足すと崩れる
A15: 自動検査 | B15: public/verify-report.json を参照 | C15: 1つでも落ちたら納品しない
A16: 運用の契約単位 | B16: 月単位 | C16: 前月末までの申出を翌月から適用
... A18: 公開前の状態 | B18: PLACEHOLDER=True（電話番号・住所が仮） | C18: 公開前に False にする。検査が WARN で見張っている
A20: 未解決: 契約確認・フォーム受信・事業者情報・屋号確認・保守の提供体制。撮影は別見積もり、CMS商品は受付準備中。

Sheet 料金レバー
A2: 料金レバー（ここだけ直す）
A3: 青い数字は試算用の入力。料金の正本はサイトです。支援は月単位・前月末の申出で変更できます。
B5: 項目 | C5: 値 | D5: 単位 | E5: 意味・根拠
B6: 制作（買い切り・税別）
B7: 入口をつくる | C7: 79800 | D7: 円 | E7: 1ページ・確認1回
B8: 事業の土台をつくる | C8: 198000 | D8: 円 | E8: 最大6ページ・確認2回
B9: 情報を育てる | C9: 398000 | D9: 円 | E9: 最大9ページ・受付準備中
B11: 支払・月次作業枠・外部費
B12: 着手金の割合 | C12: 0.5 | D12: 割合 | E12: 検収時に残額。自社24回分割の新規受付なし
B13: 整える 作業枠 | C13: 30 | D13: 分/月 | E13: 月合算を5分単位で切上げ。依頼ごとの切上げなし
B14: 育てる 作業枠 | C14: 90 | D14: 分/月 | E14: 通常変更と改善の合計。繰越なし
B15: 育てる 打合せ | C15: 30 | D15: 分/月 | E15: 作業枠とは別
B16: 外部費 概算 | C16: 3500 | D16: 円/月 | E16: 見積時に契約先・為替・利用量で更新。上限保証ではない
B17: 消費税率 | C17: 0.1 | D17: 割合 | E17: 税込比較用
B18: 増築時の充当期限 | C18: 12 | D18: か月 | E18: 同一事業・再利用できる構成・1回。撮影/外部費/支援は対象外
B19: 運用（月額・税別）
B20: 守る | C20: 3900 | D20: 円/月 | E20: 通常変更なし。提供条件を契約前に確認
B21: 整える | C21: 9800 | D21: 円/月 | E21: 守る＋月30分の変更
B22: 育てる | C22: 29800 | D22: 円/月 | E22: 守る＋月90分の作業と30分の打合せ
B23: 自分で管理 | C23: 0 | D23: 円/月 | E23: 外部費は別。継続作業は含まない
B24: 月額制（他社の公開料金・比較の相手）
B25: 比較する月数 | C25: 36 | D25: か月 | E25: 月額制各社が『譲渡』『契約満了』の区切りに使う月数に合わせた
B26: 月額制A社 1ページ 月額 | C26: 9800 | D26: 円 | E26: 公開料金の参考。役務は同一でない。https://www.propagateinc.com/web-design / 2026-09-14
B27: 月額制A社 2〜6ページ 月額 | C27: 14800 | D27: 円 | E27: 公開料金の参考。役務は同一でない。https://www.propagateinc.com/web-design / 2026-09-14
B28: 月額制A社 7〜12ページ 月額 | C28: 19800 | D28: 円 | E28: 公開料金の参考。役務は同一でない。https://www.propagateinc.com/web-design / 2026-09-14
B29: 月額制の初期費用 | C29: 5000 | D29: 円 | E29: 公開料金の参考。役務は同一でない。https://www.propagateinc.com/web-design / 2026-09-14
B30: 補助金（小規模事業者持続化補助金）
B31: 補助率 | C31: 0.66666667 | D31: — | E31: 3分の2
B32: 補助上限 | C32: 500000 | D32: 円 | E32: 全体の上限
B33: ウェブ関連費の上限 | C33: 300000 | D33: 円 | E33: 補助金額としての上限。経費額ではない
B34: ポータル掲載費（食べログ・公開料金／税込）
B35: プレミアム10 | C35: 110000 | D35: 円 | E35: 月額。税抜表記を1.1倍して税込に換算
B36: プレミアム5 | C36: 55000 | D36: 円 | E36: 月額。税抜表記を1.1倍して税込に換算
B37: ベーシック | C37: 27500 | D37: 円 | E37: 月額。税抜表記を1.1倍して税込に換算
B38: ライト | C38: 11000 | D38: 円 | E38: 月額。税抜表記を1.1倍して税込に換算
B39: 無料掲載 | C39: 0 | D39: 円 | E39: 月額。税抜表記を1.1倍して税込に換算
B40: 送客手数料（ディナー） | C40: 220 | D40: 円 | E40: 1人あたり・税込。新規と常連を区別しない
B41: 送客手数料（ランチ） | C41: 110 | D41: 円 | E41: 1人あたり・税込
A43: 正本: src/content/prices.ts / 2026-09-14。Excelは写しで、変更してもサイトに反映されません。 比較先: https://www.propagateinc.com/web-design（2026-09-14確認）
B45: 本人の月間時間 | C45: 140 | E45: ユーザー指定
...

Sheet 制作プラン
A2: 制作プラン（2026-09-14改定）
A3: 全額税別。外部費・撮影は別。着手50%・検収50%。支援は月単位・前月末申出で翌月変更。既存契約への遡及適用なし。
A5: 商品 | B5: 最大ページ | C5: 週の目安 | D5: 制作費 | E5: 着手時 | F5: 検収時 | G5: 提供範囲
A6: 入口をつくる | B6: 1 | C6: 2 | D6: =料金レバー!$C$7 -> 79800 | E6: =ROUNDDOWN(D6*料金レバー!$C$12,0) -> 39900 | F6: =D6-E6 -> 39900 | G6: 支給素材を使い、1ページで事業を伝える。既存の構成を選び、確認1回で仕上げます。
A7: 事業の土台をつくる | B7: 6 | C7: 4 | D7: =料金レバー!$C$8 -> 198000 | E7: =ROUNDDOWN(D7*料金レバー!$C$12,0) -> 99000 | F7: =D7-E7 -> 99000 | G7: 最大6ページでサービス・料金・信頼情報を整理。写真持込、確認2回。
A8: 情報を育てる | B8: 9 | C8: 6 | D8: =料金レバー!$C$9 -> 398000 | E8: =ROUNDDOWN(D8*料金レバー!$C$12,0) -> 199000 | F8: =D8-E8 -> 199000 | G8: 受付準備中。管理画面・記事と事例のテンプレートを提供確認後に受付を開始します。
A10: 納期は素材・承認が揃った場合の目安。情報を育てるは受付準備中。顧客名義の契約先、ソースと利用可能な素材、手順書を納品します。
A12: 入口→土台 | D12: =料金レバー!$C$8-料金レバー!$C$7 -> 118200 | G12: 同一事業・既存構成の再利用・12か月以内・1回の充当
A13: 土台→情報育成 | D13: =料金レバー!$C$9-料金レバー!$C$8 -> 200000 | G13: 受付開始後。撮影・外部実費・継続支援は充当の対象外

Sheet 運用プラン
A2: 継続支援（月額・税別）
A3: 全額税別。外部費・撮影は別。着手50%・検収50%。支援は月単位・前月末申出で翌月変更。既存契約への遡及適用なし。
A5: 商品 | B5: 月額 | C5: 月次作業枠(分) | D5: 打合せ(分) | E5: 含むもの
A6: 自分で管理 | B6: =料金レバー!$C$23 -> 0 | C6: 0 | D6: 0 | E6: 納品時の引継ぎ資料／月次監視・変更作業・継続相談は含みません
A7: 守る | B7: =料金レバー!$C$20 -> 3900 | C7: 0 | D7: 0 | E7: 定型監視・期限管理（外部サービス実費別）／週次バックアップの確認／障害時の一次切り分け（営業時間内）／通常の変更・投稿・会議は対象外
A8: 整える | B8: =料金レバー!$C$21 -> 9800 | C8: =料金レバー!$C$13 -> 30 | D8: 0 | E8: 「守る」の内容を含む／月30分の変更作業／作業履歴と使用時間の共有／枠を超える前に翌月対応か追加見積もりを選択
A9: 育てる | B9: =料金レバー!$C$22 -> 29800 | C9: =料金レバー!$C$14 -> 90 | D9: =料金レバー!$C$15 -> 30 | E9: 「守る」の内容を含む／月90分の改善作業／月30分の打合せ／施策1件の確認記録／作業枠を資料・フォーム・既存SaaS設定にも利用可／広告費・撮影・独自開発・記事の量産は対象外
A11: 外部費は比較用に月3,500円（税別）を仮置き。実費の上限ではありません。フォーム・保守の提供条件を確認してから契約します。

Sheet オプション・標準装備
A2: 追加作業の参考見積もり
A3: 全額税別。外部費・撮影は別。着手50%・検収50%。支援は月単位・前月末申出で翌月変更。既存契約への遡及適用なし。
A5: 作業 | B5: 参考額（税別） | C5: 条件
A6: ページ追加（既存構成にないもの） | B6: 33000 | C6: 原稿・写真の聞き取り込み
A7: 出張撮影 半日（別見積もり） | B7: 55000 | C7: 移動・編集・調整を含め、着手前に総額を確定
A8: 出張撮影 1日（別見積もり） | B8: 88000 | C8: 移動・編集・調整を含め、着手前に総額を確定
A9: ロゴ制作（3案・使用ルール付き） | B9: 88000 | C9: —
A10: 記事の作成（取材あり） | B10: 55000 | C10: 月次枠で完結しない記事制作は別見積もり
A11: ランディングページ 1枚 | B11: 198000 | C11: キャンペーン・単一商品向け
A12: 予約システムの連携 | B12: 55000 | C12: 月額はお客様が直接ご契約（当方は設定費のみ）
A13: 多言語対応 1言語（10ページ以下） | B13: 165000 | C13: —
A15: 金額は作業範囲を確認するための目安。撮影は移動・編集等も含めて総額を事前に合意。第三者素材・SaaSの費用と利用条件を別途明示。

Sheet 変更と継続支援
A2: 変更と継続支援
A3: 月次枠内で依頼を整理。自動追加請求・未使用分の繰越なし。
A5: 扱い | B5: 対象 | C5: 条件
A6: 枠内の例 | B6: 文章の修正・差し替え | C6: 内容と想定時間を先に確認
A7: 枠内の例 | B7: 写真の差し替え | C7: 内容と想定時間を先に確認
A8: 枠内の例 | B8: メニュー・料金の変更 | C8: 内容と想定時間を先に確認
A9: 枠内の例 | B9: 営業時間・定休日の変更 | C9: 内容と想定時間を先に確認
A10: 枠内の例 | B10: 既存テンプレートへのお知らせ投稿 | C10: 内容と想定時間を先に確認
A11: 枠内の例 | B11: 既存ページのスタッフ情報変更 | C11: 内容と想定時間を先に確認
A12: 枠内の例 | B12: 提供済みテンプレートへの事例追加 | C12: 内容と想定時間を先に確認
A13: 枠内の例 | B13: リンクの修正 | C13: 内容と想定時間を先に確認
A14: 枠内の例 | B14: 既存ページの中での並べ替え | C14: 内容と想定時間を先に確認
A16: 別見積もり | B16: 新しいページの追加 | C16: 既存の構成にないページ / 33,000円／ページ
A17: 別見積もり | B17: デザインの全面変更 | C17: 配色・レイアウトを一から作り直す場合 / 都度お見積り
... A21: 別見積もり | B21: 撮影の追加 | C21: 半日／1日 / 個別見積もり（移動・編集を含む）
A23: 月合計を5分単位で切上げ。依頼ごとに切り上げません。超過前に次月対応か追加見積もりを選択。紬の仕様不適合の修補は月次枠から引きません。

Sheet 月額制との比較
A2: 36か月の総額（外部費概算を含む）
A3: 紬は保守契約なし・制作のみ。外部実費は別途。比較先は月5回の更新を含み、紬は自分で管理します。
A5: 商品 | B5: 制作費 | C5: 任意の月次支援 | D5: 月次外部費概算 | E5: 紬の総額 | F5: 参考先の総額 | G5: 差（紬−参考先）
A6: 入口をつくる | B6: =料金レバー!$C$7 -> 79800 | C6: =料金レバー!$C$23 -> 0 | D6: =料金レバー!$C$16 -> 3500 | E6: =B6+(C6+D6)*料金レバー!$C$25 -> 205800 | F6: =料金レバー!$C$29+料金レバー!$C$26*料金レバー!$C$25 -> 357800 | G6: =E6-F6 -> -152000
A7: 事業の土台をつくる | B7: =料金レバー!$C$8 -> 198000 | C7: =料金レバー!$C$23 -> 0 | D7: =料金レバー!$C$16 -> 3500 | E7: =B7+(C7+D7)*料金レバー!$C$25 -> 324000 | F7: =料金レバー!$C$29+料金レバー!$C$27*料金レバー!$C$25 -> 537800 | G7: =E7-F7 -> -213800
A8: 情報を育てる | B8: =料金レバー!$C$9 -> 398000 | C8: =料金レバー!$C$23 -> 0 | D8: =料金レバー!$C$16 -> 3500 | E8: =B8+(C8+D8)*料金レバー!$C$25 -> 524000 | F8: =料金レバー!$C$29+料金レバー!$C$28*料金レバー!$C$25 -> 717800 | G8: =E8-F8 -> -193800
A10: 土台＋整える | B10: =料金レバー!$C$8 -> 198000 | C10: =料金レバー!$C$21 -> 9800 | D10: =料金レバー!$C$16 -> 3500 | E10: =B10+(C10+D10)*料金レバー!$C$25 -> 676800 | F10: =料金レバー!$C$29+料金レバー!$C$27*料金レバー!$C$25 -> 537800 | G10: =E10-F10 -> 139000
A12: すべて税別。紬の制作は79,800円から、保守契約なしなら紬への月額0円。外部費は概算。育てるは受付準備中。比較先は最低6か月、36か月後の継続・譲渡条件を確認。
A14: 出典: https://www.propagateinc.com/web-design（2026-09-14）。制作・更新量・所有条件・外部費の違いを契約前に比較します。

Sheet 補助金
A2: 小規模事業者持続化補助金（一般型・通常枠）（第20回）
A3: 補助率3分の2、上限500,000円。ホームページに使える分は補助金額で300,000円まで。
A5: 科目 | B5: 内容 | C5: 金額 | E5: 備考
A6: ウェブサイト関連費 | B6: 事業の土台をつくる 最大6ページ（原稿整理・写真持込） | C6: =料金レバー!$C$8 -> 198000
A7: 広報費 | B7: ショップカード・チラシ制作＋印刷1,000部 | C7: 150000
A8: 広報費 | B8: 店頭看板／のぼり デザイン＋制作 | C8: 100000
A9: 広報費 | B9: 追加撮影（商品・スタッフ）1日 | C9: 88000
A10: 広報費 | B10: メニュー表・料金表のデザイン＋印刷 | C10: 64000
B11: 合計 | C11: =SUM(C6:C10) -> 600000
A13: 補助額と自己負担の計算
A14: 端数は切り捨て。ウェブ関連費には補助金額の上限がある。
B16: 計算 | C16: 金額 | E16: 意味
B17: ウェブサイト関連費 | C17: =SUMIF($A$6:$A$10,"ウェブサイト関連費",$C$6:$C$10) -> 198000 | E17: 経費額。ここから補助率をかける
B18: 広報費 | C18: =SUMIF($A$6:$A$10,"広報費",$C$6:$C$10) -> 402000 | E18: チラシ・看板・撮影・メニュー表
B19: ウェブの補助額 | C19: =MIN(FLOOR(C17*料金レバー!$C$31,1),料金レバー!$C$33) -> 132000 | E19: 補助率をかけたあと、300,000円で頭打ち
B20: 広報費の補助額 | C20: =MIN(FLOOR(C18*料金レバー!$C$31,1),料金レバー!$C$32-C19) -> 268000 | E20: 全体の上限から、ウェブの補助額を引いた残りが天井
B21: 補助額の合計 | C21: =MIN(C19+C20,料金レバー!$C$32) -> 400000 | E21: 全体の上限500,000円
B22: 自己負担（実質） | C22: =$C$11-C21 -> 200000 | E22: ここがお客様のご負担。ただし全額を立て替えたあとに入金される
A24: 先に伝えておくこと
A25: ここを黙っていると、あとで必ず揉める。
A27: 項目 | B27: 内容
A28: 採択率 | B28: 47.2%（第19回は16,576件の申請に対し7,819件が採択）。「必ず通ります」「実質無料です」とは言わない。通らなかった場合の扱いは契約前に書面で決める（ベーシックに縮小するか、白紙に戻すか）
A29: 入金の時期 | B29: 精算払い。お客様がいったん全額を立て替えて、実績報告のあとに入金される
A30: 申請の代行 | B30: できない。2026年1月の行政書士法改正で、名目を問わず報酬を得て申請書類を作成することが明確に違反になった。制作費に申請代行を含めることもできない。計画づくりは商工会・商工会議所へ（無料。様式4の発行窓口でもある）
A31: 当方が出すもの | B31: 見積書と、効果の根拠になる資料。それをお客様が自分の言葉で申請書に書く
A32: 着手の時期 | B32: 交付決定の前に着手しない。契約書の日付も決定日より後にする。ここがいちばん大事
A33: 相見積り | B33: 1件50万円（税込）を超える発注には2者以上の見積りが必要。最初に伝える
A34: 申請の締切 | B34: 2026年12月15日（火）17:00
A35: 様式4（商工会） | B35: 2026年12月4日（金）まで。年末は混むので11月上旬までが安全
A36: なぜ単独で申請できないか | B36: この補助金はホームページ関連費だけでは申請できない。必ず他の経費と一緒に出す。だから同じ写真・同じ文章でチラシ・看板・メニュー表までまとめて作る（撮影も原稿も一度で済むので、別々に頼むより安い）
A38: 市町村ごとの補助金もある。ただし「ホームページ補助金」という名前ではなく、「販路開拓」「産業振興」「DX推進」の枠のなかの1メニューになっていることが多い。予算に達すると早期終了する（ある県では9月30日締切の制度が8月28日に終了した）。毎週チェックする。

Sheet ポータル掲載費
A2: 掲載費と支援費の差額（税込）
A3: 掲載費変更による集客への影響は別。制作費と予約等の追加費も加えて判断します。
A5: プラン | B5: 掲載料/月 | C5: 整える＋外部費/月 | D5: 差額/月 | E5: 条件
A6: プレミアム10 | B6: =料金レバー!$C$35 -> 110000 | C6: =ROUND((料金レバー!$C$21+料金レバー!$C$16)*(1+料金レバー!$C$17),0) -> 14630 | D6: =B6-C6 -> 95370 | E6: 掲載を無料にできる契約の場合。送客手数料は別途
A7: プレミアム5 | B7: =料金レバー!$C$36 -> 55000 | C7: =ROUND((料金レバー!$C$21+料金レバー!$C$16)*(1+料金レバー!$C$17),0) -> 14630 | D7: =B7-C7 -> 40370 | E7: 掲載を無料にできる契約の場合。送客手数料は別途
A8: ベーシック | B8: =料金レバー!$C$37 -> 27500 | C8: =ROUND((料金レバー!$C$21+料金レバー!$C$16)*(1+料金レバー!$C$17),0) -> 14630 | D8: =B8-C8 -> 12870 | E8: 掲載を無料にできる契約の場合。送客手数料は別途
A9: ライト | B9: =料金レバー!$C$38 -> 11000 | C9: =ROUND((料金レバー!$C$21+料金レバー!$C$16)*(1+料金レバー!$C$17),0) -> 14630 | D9: =B9-C9 -> -3630 | E9: 掲載を無料にできる契約の場合。送客手数料は別途
A10: 無料掲載 | B10: =料金レバー!$C$39 -> 0 | C10: =ROUND((料金レバー!$C$21+料金レバー!$C$16)*(1+料金レバー!$C$17),0) -> 14630 | D10: =B10-C10 -> -14630 | E10: 掲載を無料にできる契約の場合。送客手数料は別途
A12: 予約人数の単純目安 | B12: =ROUNDUP(C6/料金レバー!$C$40,0) -> 67 | E12: ディナー税込220円/人の仮定。制作費を除く支援費＋外部費との比較
A14: 食べログ公開料金を元にした参考。最新の契約・手数料を個別確認。掲載をやめる提案を先に決めず、予約減少による限界利益への影響を確かめます。

Sheet 納品する仕様20
A2: 全業種に共通する20項目
A3: 数字が出ているものだけを入れる。20項目すべてを自動でチェックし、1つでも落ちたら納品しない。
A5: # | B5: 区分 | C5: 項目 | D5: 根拠（なぜ入れるか）
A6: 1 | B6: 情報 | C6: 電話番号を全ページの上部に、文字で置きます | D6: 画像にした電話番号はGoogleが読めず、スマホでタップしても発信できません。連絡先を決める段階で重視される要素の1位は「営業時間・住所・電話がはっきり書かれていること」（32%）です。
A7: 2 | B7: 情報 | C7: 営業時間を、定休日・臨時休業・年末年始まで書きます | D7: 同じく1位の要素です。文字で書くので検索にも反映されます。
A8: 3 | B8: 情報 | C8: 住所・地図・アクセス・駐車場の有無を書きます | D8: お店を探す段階で最も見られている要素が「住所・近さ」（44%）。Googleマップ経由の行動の38%が経路検索です。
A9: 4 | B9: 情報 | C9: 料金を必ず何らかの形で出します | D9: 連絡しなかった理由の2位が「料金が不明確」（32%）で、星の評価（30%）より上です。「お見積り」でも、算出の考え方と目安の幅は出します。ただし安く見せることはしません。
A10: 5 | B10: 情報 | C10: 業種によって、電話とフォームのどちらを主役にするかを入れ替えます | D10: 調査では士業は電話が56%・フォームが44%、美容室はフォームが92%・電話が8%と真逆でした。同じ作りを全業種に当てるのは合いません。
A11: 6 | B11: 情報 | C11: 対応エリアを書きます（工務店・士業は市町村ごとに） | D11: 「近さ」はGoogleが公表しているマップの順位の3要因のひとつです。
A12: 7 | B12: 中身 | C12: 写真は明るく、実物を撮ります | D12: 飲食店のサイトを見て来店をやめた理由の36%が「料理写真が良くない」。写真が選択に影響すると答えた人は87%です。
A13: 8 | B13: 中身 | C13: スタッフ・代表の顔写真と人柄が伝わる紹介を入れます | D13: 税理士を選ぶときに最も重視された項目の1位は「相談しやすさ・人柄・相性」（21%）でした。
A14: 9 | B14: 中身 | C14: 実績・事例は一覧と詳細の2段にします（工務店は最優先） | D14: 注文住宅の購入者調査では、施工事例が「参考になった」58%・「決め手になった」57%で両方1位。一方、会社紹介は参考58%→決め手11%に落ちるので、そこには工数を割きません。
A15: 10 | B15: 中身 | C15: お客様の声には、依頼した旨を明記します | D15: 謝礼や依頼があるものは、事業者の表示だと分かるように書くことが景品表示法で必要です（2023年10月施行）。守らない制作会社が多いので、テンプレートに入れています。
A16: 11 | B16: 中身 | C16: 料金・費用・選び方の解説を3〜5本だけ書きます | D16: 料金についての検索では、8割以上でAIの回答が表示されます。ここがAIに引用される入口です。ただし記事の量産はしません。ページ数と引用されやすさの相関はほぼゼロでした。
A17: 12 | B17: 技術 | C17: スマホとパソコンで同じ内容にします。スマホ用に内容を削りません | D17: Googleが「モバイルのコンテンツを減らすと流入の減少を想定すべき」と明記しています。
... A25: 20 | B25: 運用 | C25: 納品後の運用は「口コミの鮮度を保つこと」に集約します | D25: 74%が直近3か月以内の口コミを重視し、47%は口コミが20件未満のお店を使わず、42%は口コミに返信していないお店を避け、50%は定型的な返信だと選ぶ確率が下がります。
A27: 区分の意味
B29: 情報 | C29: 調査で「連絡されない理由」の1位と2位だった項目です。
B30: 中身 | C30: 見た人が判断材料にしている中身です。
B31: 技術 | C31: 数字で効果が確認できるものだけ。やらないことも決めています。
B32: 運用 | C32: 作ったあとに効く部分です。

Sheet 売らないもの
A2: 売らないと決めているもの
A3: これらを売っている制作会社は実際にある。根拠がないものを売らないと決めた。同じ商品棚に並ばないことが、いちばんの違い。
A5: 売らないもの | B5: 理由
A6: llms.txt の設置 | B6: Googleが公式に「不要」と明記しています。Googleの担当者も「どのAIシステムも使っていない」と発言しています。
A7: AI検索最適化（LLMO） | B7: Googleの公式ガイドが、構造化データもコンテンツの分割もAI向けの書き方も不要だと明言しています。
A8: FAQの構造化データ | B8: 2026年5月7日に、Google検索での表示が終了しました。
A9: 表示速度スコア100点 | B9: Google自身が「SEOのために満点を狙うのは時間の使い方として最善ではない」と書いています。2.5秒以内を守れば十分です。
A10: 「アクセシビリティ義務化対応」 | B10: 2024年に義務化されたのは合理的配慮の提供で、ウェブアクセシビリティ自体は義務化されていません。
A12: あわせて約束しないこと：検索順位（順位を保証する会社があれば疑ったほうがいい）／新規客が増えること（美容室の市場は前年比5.9%縮小）／補助金の採択。確実にできるのは、手数料の削減と再来店の導線づくり。そこは数字で確認できる。

Sheet 業種別
A2: 業種ごとに何を作るか
A3: 値段は業種で変えない。変わるのは作るページの中身。中央値は846件の実発注データより。
A5: 業種 | B5: 推奨プラン | C5: 制作費の中央値 | D5: 必ず入れるもの | E5: 作らないもの | F5: 財源（いまの費用）
A6: 飲食店 | B6: 事業の土台をつくる（6ページ） | C6: 52.8万円 | D6: ・メニューを文字で載せます（PDFや画像にしません） ・支給の料理写真を配置します（撮影は別見積もり） ・地図・アクセス・駐車場 ・電話と予約の両方を置きます ・営業時間（臨時休業・年末年始まで） | E6: ・Googleの飲食店カルーセルを狙う設定 | F6: 食べログのベーシックプラン（税込27,500円）を無料プランに戻しても、ネット予約は固定費0円で使えます。常連さんの予約1件ごとに220円かかる構造から抜けます。
A7: 工務店・建設 | B7: 情報を育てる（9ページ・受付準備中） | C7: 63.4万円 | D7: ・施工事例を、増やしていける形で作ります ・性能・構造の説明 ・お客様の声（依頼した旨を明記して） ・対応エリアを市町村ごとに ・問い合わせフォームを主役にします | E7: ・会社紹介の作り込み ・「建設業許可番号の掲載は法律で必要」という説明 | F7: この業種はポータルサイトより広告費の見直しが効きます。商圏の外への配信、成約ゼロの検索語、指名検索への過剰な出稿を整理します。
A8: 美容室・サロン | B8: 事業の土台をつくる（6ページ） | C8: 54.8万円 | D8: ・全メニューの料金表（税込・追加料金の条件まで） ・予約ボタンを最優先で置きます ・スタイリストの紹介（顔・得意なこと・指名のしかた） ・スタイルの写真 ・電話も残します（50代以上のお客様向け） | E8: ・新規のお客様が増えるという約束 | F8: ホットペッパービューティーの掲載料は公開されていないので、まず直近の請求書を見せてください。無料プランが存在せず、予約売上の2%が手数料としてかかります。
A9: 士業・専門事務所 | B9: 情報を育てる（9ページ・受付準備中） | C9: 40.0万円 | D9: ・料金の体系を明示します（範囲・別途費用まで） ・代表・担当者の顔写真と経歴、人柄が伝わる紹介 ・取扱分野を具体的に分けて書きます ・電話を最上部に固定します ・返答までの時間を書きます | E9: ・弁護士の方の広告表現 | F9: この業種は広告の獲得単価が高く（3万〜5万円という目安があります）、整理の余地が大きいです。商圏外への配信と、成約ゼロの検索語から見ます。
A11: どの業種でも、作ったものはお客様のもの。ドメインは初日からお客様の名義で取り、ソースコードも撮影した写真の元データも渡す。やめても残る。

Sheet ページ一覧
A2: サイトの構成（21ページ）
A3: ヘッダーに入るのは4本だけ。先頭は一番の主張に使う。
A5: # | B5: ファイル | C5: 見出し | D5: 役割
A6: 1 | B6: index.html | C6: ホーム | D6: トップ。主張→地代の比較→料金→総額→補助金→業種→正直に、の順
A7: 2 | B7: owned.html | C7: 借地と所有 | D7: 一番の主張。借地と所有。他のページはここを支える材料
A8: 3 | B8: price.html | C8: 料金 | D8: 料金の全部。料金と作業枠は2026-09-14改定。着手50%・検収50%、継続支援は月単位。
A9: 4 | B9: unlimited.html | C9: 変更は何回でも | D9: 料金と作業枠は2026-09-14改定。着手50%・検収50%、継続支援は月単位。曖昧にすると揉める
A10: 5 | B10: source.html | C10: ソースコードの納品 | D10: ソースコードを渡す理由と、渡すものの中身
A11: 6 | B11: cost-cut.html | C11: 掲載費の見直し | D11: 掲載費の見直し。新しい予算の前に、いまの費用を見る
A12: 7 | B12: subsidy.html | C12: 補助金 | D12: 補助金の手順と注意点。採択率も自己負担も先に出す
A13: 8 | B13: spec.html | C13: 納品する仕様 | D13: 納品する仕様20項目＋売らないもの5件。機械で検証
A14: 9 | B14: flow.html | C14: 制作の流れ | D14: 制作の流れ
A15: 10 | B15: works.html | C15: 制作事例 | D15: 制作事例。まだ1件目だと正直に書く
A16: 11 | B16: faq.html | C16: よくあるご質問 | D16: 電話の前に確かめたいこと
A17: 12 | B17: about.html | C17: 私たちについて | D17: 2人でやっていること
... A26: 21 | B26: 404.html | C26: ページが見つかりません | D26: 行き止まりにせず、電話とトップに戻す
A28: ヘッダーに入る4本：借地と所有／料金／掲載費の見直し／補助金。robots.txt と sitemap.xml も出力する。llms.txt は作らない（根拠がないため。検査が見張っている）。

Sheet 配布用_料金表
A2: 紬｜料金表
A3: 全額税別。外部費・撮影は別。着手50%・検収50%。支援は月単位・前月末申出で翌月変更。既存契約への遡及適用なし。
A5: 商品 | B5: ページ/支援枠 | C5: 税別料金 | D5: 着手時 | E5: 検収時 | F5: 備考
A6: 入口をつくる | B6: 1ページ以内 | C6: =料金レバー!$C$7 -> 79800 | D6: =ROUNDDOWN(C6*料金レバー!$C$12,0) -> 39900 | E6: =C6-D6 -> 39900 | F6: 支給素材を使い、1ページで事業を伝える。既存の構成を選び、確認1回で仕上げます。
A7: 事業の土台をつくる | B7: 6ページ以内 | C7: =料金レバー!$C$8 -> 198000 | D7: =ROUNDDOWN(C7*料金レバー!$C$12,0) -> 99000 | E7: =C7-D7 -> 99000 | F7: 最大6ページでサービス・料金・信頼情報を整理。写真持込、確認2回。
A8: 情報を育てる | B8: 9ページ以内 | C8: =料金レバー!$C$9 -> 398000 | D8: =ROUNDDOWN(C8*料金レバー!$C$12,0) -> 199000 | E8: =C8-D8 -> 199000 | F8: 受付準備中。管理画面・記事と事例のテンプレートを提供確認後に受付を開始します。
A11: 自分で管理 | B11: 0分/月 | C11: =料金レバー!$C$23 -> 0 | F11: 納品時の引継ぎ資料／月次監視・変更作業・継続相談は含みません
A12: 守る | B12: 0分/月 | C12: =料金レバー!$C$20 -> 3900 | F12: 定型監視・期限管理（外部サービス実費別）／週次バックアップの確認／障害時の一次切り分け（営業時間内）／通常の変更・投稿・会議は対象外
A13: 整える | B13: 30分/月 | C13: =料金レバー!$C$21 -> 9800 | F13: 「守る」の内容を含む／月30分の変更作業／作業履歴と使用時間の共有／枠を超える前に翌月対応か追加見積もりを選択
A14: 育てる | B14: 90分/月 | C14: =料金レバー!$C$22 -> 29800 | F14: 「守る」の内容を含む／月90分の改善作業／月30分の打合せ／施策1件の確認記録／作業枠を資料・フォーム・既存SaaS設定にも利用可／広告費・撮影・独自開発・記事の量産は対象外
A16: サーバー・ドメイン・CMS・フォーム等は実費。納品時の引継ぎを含みます。支援を終了しても外部契約の費用は残ります。第三者の素材・サービスはその利用条件に従います。
A18: 増築時の充当: 同一事業・再利用できる構成・納品12か月以内・1回のみ。通常の変更は月合計を5分単位で切上げ、繰越なし。枠を超える前に次月対応か別見積もりを選択。

Sheet 配布用_36か月の総額
A2: 36か月の総額（外部費概算を含む）
A3: 紬は保守契約なし・制作のみ。外部実費は別途。比較先は月5回の更新を含み、紬は自分で管理します。
A5: 商品 | B5: 制作費 | C5: 任意の月次支援 | D5: 月次外部費概算 | E5: 紬の総額 | F5: 参考先の総額 | G5: 差（紬−参考先）
A6: 入口をつくる | B6: =料金レバー!$C$7 -> 79800 | C6: =料金レバー!$C$23 -> 0 | D6: =料金レバー!$C$16 -> 3500 | E6: =B6+(C6+D6)*料金レバー!$C$25 -> 205800 | F6: =料金レバー!$C$29+料金レバー!$C$26*料金レバー!$C$25 -> 357800 | G6: =E6-F6 -> -152000
A7: 事業の土台をつくる | B7: =料金レバー!$C$8 -> 198000 | C7: =料金レバー!$C$23 -> 0 | D7: =料金レバー!$C$16 -> 3500 | E7: =B7+(C7+D7)*料金レバー!$C$25 -> 324000 | F7: =料金レバー!$C$29+料金レバー!$C$27*料金レバー!$C$25 -> 537800 | G7: =E7-F7 -> -213800
A8: 情報を育てる | B8: =料金レバー!$C$9 -> 398000 | C8: =料金レバー!$C$23 -> 0 | D8: =料金レバー!$C$16 -> 3500 | E8: =B8+(C8+D8)*料金レバー!$C$25 -> 524000 | F8: =料金レバー!$C$29+料金レバー!$C$28*料金レバー!$C$25 -> 717800 | G8: =E8-F8 -> -193800
A10: 土台＋整える | B10: =料金レバー!$C$8 -> 198000 | C10: =料金レバー!$C$21 -> 9800 | D10: =料金レバー!$C$16 -> 3500 | E10: =B10+(C10+D10)*料金レバー!$C$25 -> 676800 | F10: =料金レバー!$C$29+料金レバー!$C$27*料金レバー!$C$25 -> 537800 | G10: =E10-F10 -> 139000
A12: すべて税別。紬の制作は79,800円から、保守契約なしなら紬への月額0円。外部費は概算。育てるは受付準備中。比較先は最低6か月、36か月後の継続・譲渡条件を確認。
A14: 出典: https://www.propagateinc.com/web-design（2026-09-14）。制作・更新量・所有条件・外部費の違いを契約前に比較します。

Sheet 月140時間の計画
A1: 項目 | B1: 入力または算式 | C1: 出所・意味
A2: 本人の月間時間 | B2: =料金レバー!$C$45 -> 140 | C2: ユーザー指定
A3: 営業・事務等 | B3: =料金レバー!$C$46 -> 28 | C3: 仮定 / tools/pricing/proposal.json
A4: 予備 | B4: =料金レバー!$C$47 -> 28 | C4: 仮定 / tools/pricing/proposal.json
A5: 契約可能な時間 | B5: =B2-B3-B4 -> 84 | C5: 計算結果。予備時間を売らない
A6: 本人時間の評価単価 | B6: =料金レバー!$C$48 -> 5000 | C6: 未検証の仮定・税引後手取りではない
A7: 本人時間の全体原価 | B7: =B2*B6 -> 700000 | C7: 全140時間を一度だけ評価
A8: モデル制作時間 | B8: =料金レバー!$C$49+料金レバー!$C$50 -> 41 | C8: 土台1件15h＋情報育成1件26h。CMS提供開始後の条件付き
A9: モデル支援時間 | B9: =料金レバー!$C$51*料金レバー!$C$54+料金レバー!$C$52*料金レバー!$C$55+料金レバー!$C$53*料金レバー!$C$56 -> 28.5 | C9: 守る10社・整える16社・育てる6社。未検証工数
A10: 契約時間の余白 | B10: =B5-B8-B9 -> 14.5 | C10: 営業・予備を別に確保したうえでの余白
A11: 25%の工数増での余白 | B11: =B5-(B8+B9)*(1+料金レバー!$C$57) -> -2.875 | C11: 負なら追加受注を止める。未検証の感度ケース
